Workbook

Sheet Instructions and Overview
A1: This sheet is updated periodically from DRIs that would be the source of information.
A2: To update information, comment on the cell with the requested changes and tag Amelia Baldwin Jan De Jager
A3: Changes requests will be confirmed into the sheet.
A5: Last known update
A6: 45932

Sheet School Data
B1: Hidden | C1: Alpha School Austin | D1: Alpha High School | E1: Alpha School Miami | F1: Alpha School Brownsville | H1: Texas Sports Academy | I1: GT School | J1: Nova Academy Austin | K1: Nova Academy Bastrop | L1: NextGen Academy | M1: Waypoint Academy | N1: Montessorium Cedar Park | O1: Alpha School Scottsdale | P1: Alpha School Fort Worth | Q1: Alpha School San Francisco | R1: Alpha School Palm Beach | S1: Alpha School Plano | T1: Alpha Anywhere Center | U1: Alpha School Santa Barbara | V1: Alpha School Lake Forest | W1: Alpha School Chantilly | X1: Alpha School Charlotte | Y1: Alpha School Raleigh | Z1: Alpha School Tampa | AA1: Alpha School Dorado | AC1: Alpha School Palo Alto | AD1: Alpha School Piedmont | AE1: Alpha School Santa Monica | AG1: Alpha School Roswell | AH1: Alpha School Kirkland | AI1: Alpha School Dorado | AL1: Single-user 2hr learning
A2: jackie | B2: Default | C2: Alpha School Austin | D2: Alpha High School Austin | E2: Alpha School Miami | F2: Alpha School Brownsville | G2: Alpha High School Brownsville | H2: Texas Sports Academy | I2: GT School | J2: Nova Academy Austin | K2: Nova Academy Bastrop | L2: NextGen Academy | M2: Waypoint Academy | N2: Montessorium Cedar Park | O2: Alpha School Scottsdale | P2: Alpha School Fort Worth | Q2: Alpha School San Francisco | R2: Alpha School Palm Beach | S2: Alpha School Plano | T2: Alpha New York | U2: Alpha School Santa Barbara | V2: Alpha School Orange County | W2: Alpha School Chantilly | X2: Alpha School Charlotte | Y2: Alpha School Raleigh | Z2: Alpha School Tampa | AA2: Alpha School Dorado | AB2: Alpha School Chicago | AC2: Alpha School Palo Alto | AD2: Alpha School East Bay | AE2: Alpha School Santa Monica | AF2: Alpha School The Woodlands | AG2: Alpha School Atlanta | AH2: Alpha School Kirkland | AI2: Alpha School Bradley Hills | AJ2: Alpha School Boston | AK2: - | AL2: Alpha Anywhere | AM2: Carrollton | AN2: Who to contact to confirm data
A3: State Details | C3: Texas | D3: Texas | E3: Florida | F3: Texas | G3: Texas | H3: Texas | I3: Texas | J3: Texas | K3: Texas | L3: Texas | M3: Texas | N3: Texas | O3: Arizona | P3: Texas | Q3: California | R3: Florida | S3: Texas | T3: (branded as "Alpha" for now) New York | U3: California | V3: California | W3: Virginia | X3: North Carolina | Y3: North Carolina | Z3: Florida | AA3: Puerto Rico | AB3: Illinois | AC3: California | AD3: California | AE3: California | AF3: Texas | AG3: Georgia | AH3: Washington | AI3: Maryland | AJ3: Boston | AK3: - | AL3: Online | AM3: Texas
A4: Location | C4: Austin | D4: Austin | E4: Miami | F4: Brownsville | G4: Brownsville | H4: Austin | I4: Georgetown | J4: Austin | K4: Bastrop | L4: Austin | M4: Dripping Springs | N4: Brushy Creek / Cedar Park | O4: Scottsdale | P4: Fort Worth | Q4: San Francisco | R4: Palm Beach | S4: Plano | T4: New York | U4: Santa Barbara | V4: Lake Forest | W4: Chantilly | X4: Charlotte | Y4: Raleigh | Z4: Tampa | AA4: Dorado | AB4: Chicago | AC4: Palo Alto | AD4: Piedmont | AE4: Santa Monica | AF4: The Woodlands/Houston | AG4: Roswell (Atlanta) | AH4: Kirkland (Seattle) | AI4: Bethseda | AJ4: Massachusetts | AK4: - | AL4: Online | AM4: Carolton
A5: location on website? | B5: https://alpha.school/locations/ | C5: Per Default | D5: Per Default | E5: Per Default | F5: Per Default | G5: No | I5: https://gt.school/ | J5: https://novaacademy.school/ | K5: https://novaacademy.school/ | L5: https://nextgenacademy.school/ | M5: https://waypointacademy.school/ | N5: https://montessorium.com/ | O5: Per Default | P5: Per Default | Q5: Per Default | R5: Per Default | S5: Per Default | T5: Per Default | U5: Per Default | V5: Per Default | W5: Per Default | X5: Per Default | Y5: Per Default | Z5: Per Default | AA5: Per Default | AB5: Per Default | AC5: Per Default | AD5: Per Default | AE5: Per Default | AF5: Yes - location announced soon | AG5: No | AH5: No | AI5: No | AJ5: No | AK5: - | AM5: https://sportsacademy.school/locations
A6: => Location Type | B6: => Location Type | C6: Leased from 5Y (controlled enity) | D6: Leased from 3rd party | E6: Leased from 3rd party | F6: Owned by LOE | G6: TBD | H6: Leased from 5Y (controlled enity) | I6: Leased from 5Y (controlled enity) | J6: Leased from 3rd party | K6: Leased from 3rd party | L6: Leased from 3rd party | M6: Leased from 3rd party | N6: Leased from 3rd party | O6: Leased from 3rd party (Guidepost) | P6: Leased from 3rd party | Q6: Leased from 3rd party | R6: Leased from 3rd party (Guidepost) | S6: Leased from 3rd party (Guidepost) | T6: Leased from 3rd party | U6: Leased from 3rd party | V6: Leased from 3rd party (Guidepost) | W6: Leased from 3rd party (Guidepost) | X6: Leased from 3rd party (Guidepost) | Y6: Leased from 3rd party (Guidepost) | Z6: Leased from 3rd party | AA6: Leased from 3rd party | AC6: Leased from 3rd party | AD6: Leased from 3rd party | AE6: Leased from 3rd party | AF6: Leased from 3rd party | AG6: Leased from 3rd party | AH6: Leased from 3rd party | AI6: Leased from 3rd party | AK6: - | AL6: Online | AM6: -
A7: => School Model (Proposed Idea) | B7: => School Model (Proposed Idea) | C7: Alpha Growth | D7: Alpha Growth | E7: Alpha Growth | F7: Low Cost Model | H7: Sports Academy | I7: Gifted and Talented | J7: Low Cost Model | K7: Low Cost Model | L7: eSports | M7: Outdoor Academy | N7: Montessorium | O7: Alpha Microschool | P7: Alpha Microschool | Q7: Alpha Microschool | R7: Alpha Microschool | S7: Alpha Microschool | T7: Alpha Microschool | U7: Alpha Microschool | V7: Alpha Microschool | W7: Alpha Microschool | X7: Alpha Microschool | Y7: Alpha Microschool | Z7: Alpha Microschool | AA7: Alpha Microschool | AB7: Alpha Microschool | AC7: Alpha Microschool | AD7: Alpha Microschool | AE7: Alpha Microschool | AF7: Alpha Microschool | AG7: Alpha Microschool | AH7: Alpha Microschool | AI7: Alpha Microschool | AJ7: Alpha Microschool | AK7: - | AL7: Not a 'school' - homeschool curriculum
A8: 1. Tuition List Price | B8: => Tuition per Student per Year | C8: 40000 | D8: 40000 | E8: 50000 | F8: $10,000 Space X Subsidy: $5,000 | H8: 25000 | I8: 25000 | J8: 15000 | K8: 15000 | L8: 25000 | M8: 30000 | N8: Tuition will be the current amount (varies by family, but < 25k) for SY25/26 Tuition will be 25k for SY26/27 and beyond | O8: 40000 | P8: 40000 | Q8: 75000 | R8: 50000 | S8: 50000 | T8: $65,000 increasing to $75,000/yr at some point (not publicly announced yet) | U8: $50,000 increasing to $75,000/yr at some point (not publicly announced yet) | V8: 50000 | W8: 65000 | X8: 45000 | Y8: 45000 | Z8: 40000 | AA8: 50000 | AB8: 55000 | AC8: 75000 | AD8: 65000 | AE8: 50000 | AF8: 40000 | AG8: 40000 | AH8: 50000 | AJ8: 65000 | AK8: - | AL8: $10,000/year for 2HL | AM8: -
A9: 2. Lunch | B9: => Lunch is offered at all schools => The default pricing is $200/month | C9: Per Default | D9: Per Default | E9: 2025/26: Included in tuition From SY2026/27 Per Default | F9: Legacy students: Included in tuition New students: $100/month | H9: Per Default | I9: Per Default | J9: Included/No charge - 25/26 $100/month beginning in 26/27 | K9: Not offered for 25/26 | L9: Per Default | M9: Per Default | N9: Not offered for 25/26 Not offered for 26/27 | O9: Per Default | P9: Per Default | Q9: Per Default | R9: Per Default | S9: Per Default | T9: Per Default | U9: Per Default | V9: Per Default | W9: Per Default | X9: Per Default | Y9: Per Default | Z9: Per Default | AA9: TBD | AC9: Per Default | AD9: Per Default | AF9: TBD | AG9: Per Default | AI9: TBD | AK9: - | AL9: N/a | AM9: N/a
A10: 2.1 Lunch Vendor | B10: Sifted | C10: Per Default | D10: Per Default | E10: Fresh Dining Food | F10: Nellie's Cakes Catering | H10: Per Default | I10: Per Default | J10: Per Default | K10: N/A | L10: Per Default | M10: TBD | N10: N/A | O10: Urban Phoenix | P10: Moses SK Catering | Q10: Per Default | R10: Made You Hungry Catering | S10: Moses SK Catering | T10: Per Default | U10: 30 Acres Catering | V10: Taste Catering | W10: TBD | X10: TBD | Y10: TBD | Z10: TBD | AA10: TBD | AC10: Per Default | AD10: Per Default | AE10: TBD | AF10: TBD | AG10: Per Default | AH10: Per Default | AI10: TBD | AK10: - | AM10: N/a
A11: 3. Discounts / Financial Aid | B11: - | C11: - | D11: - | E11: - | F11: - | H11: - | I11: - | J11: - | K11: - | L11: - | M11: - | N11: - | O11: - | P11: - | Q11: - | R11: - | S11: - | T11: - | U11: - | V11: - | W11: - | X11: - | Y11: - | Z11: - | AA11: - | AF11: - | AI11: - | AK11: - | AL11: - | AM11: -
A12: 3.1 Deposit | B12: => The default pricing is $1,000, refundable | C12: Per Default | D12: Per Default | E12: Per Default | F12: Per Default | H12: Per Default | I12: Per Default | J12: $500 deposit | K12: $500 deposit | L12: Per Default | M12: Per Default | N12: Per Default | O12: Per Default | P12: Per Default | Q12: Per Default | R12: Per Default | S12: Per Default | T12: Per Default | U12: Per Default | V12: Per Default | W12: Per Default | X12: Per Default | Y12: Per Default | Z12: Per Default | AA12: Per Default | AB12: Per Default | AF12: Per Default | AI12: Per Default | AK12: - | AL12: N/A | AM12: N/A
A13: 3.2 Founding family discount | B13: - First 25 students enrolled have $10k/yr tuition credit for 5 years from school opening year | C13: N/a | D13: N/a | E13: - Eligible to all students with paid deposits by 8/15/2025 Families who enroll by August 15, 2025, receive a $10,000 tuition credit per year per student. Applicable for SY 2024/25 and 2025/26 only New family members enrolling after August 15, 2025 will not receive the FF tuition credit. The $10k discount applies every year through the 2028-29 school year (first year not offered would be 2029-2030 for clarity) for students that enrolled by August 15, 2025 | F13: N/a | H13: N/a | I13: $10k eligible up to first 50 students enrolled. Applied for one year. (Families receive ten, $1,000 credits) | J13: Joe is providing scholarships to all kids for the first year. Goal will be to get everything setup to accept vouchers starting next year. Per MP, no new students enrolled for 25/26, only existing students at $0. | K13: 25-26 $10,000 tuition credit in good faith for ESA vouchers | L13: 20 scholarships @ $10k each max. 1 year grades 3-5 only families w/ AGI under $150k | M13: Proposed on 10/14: Up to $8,000 off tuition per year (for up to 3 years, max $10,000 per year) In exchange, families agree to: Provide 2 qualified referrals per year (families who apply to Waypoint) Host one small dinner or gathering per year (Waypoint will support logistics, materials, and representation) Receive an additional $1,000 off for each referred family that enrolls at Waypoint Re-evaluated every year | N13: No FF tuition credit | O13: Per Default | P13: Per Default | Q13: Per Default | R13: Per Default | S13: Per Default | T13: Per Default | U13: Per Default | V13: Per Default | W13: $20,000, if deposited 1/7/26 and after. Deposits before this time are $10,000 | X13: Per Default | Y13: Per Default | Z13: Per Default | AA13: Per Default | AB13: Per Default | AF13: Per Default | AI13: Per Default | AK13: - | AL13: Active Employee 30% discount | AM13: -
A14: 3.3 Sibling discount | B14: - Annual Tuition is reduced by 5% for each additional child enrolled. - The Sibling Discount is applied to each younger student and is only applicable when more than one child in the same family is enrolled during the same School Year. - not applied for student 1 | C14: Per Default | D14: Per Default | E14: Per Default | F14: Per Default | H14: Per Default | I14: Per Default | J14: Per Default | K14: Per Default | L14: Per Default | M14: Per Default | N14: Per Default | O14: Per Default | P14: Per Default | Q14: Per Default | R14: Per Default | S14: Per Default | T14: Per Default | U14: Per Default | V14: Per Default | W14: Per Default | X14: Per Default | Y14: Per Default | Z14: Per Default | AA14: Per Default | AB14: Per Default | AF14: Per Default | AI14: Per Default | AK14: - | AL14: Per Default | AM14: -
A15: 3.4 Merit Scholarships | B15: - limited and merit-based - awarded to students who are outstanding academically/personally and Highly engaged in ambassadorship or significant school promotion efforts - all nominations must go through MacKenzie | C15: Per Default | D15: Per Default | E15: Per Default | F15: Per Default | H15: Per Default | I15: Per Default | J15: Per Default | K15: Per Default | L15: Per Default | M15: Per Default | N15: Per Default | O15: Per Default | P15: Per Default | Q15: Per Default | R15: Per Default | S15: Per Default | T15: Per Default | U15: Per Default | V15: Per Default | W15: Per Default | X15: Per Default | Y15: Per Default | Z15: Per Default | AA15: Per Default | AB15: Per Default | AF15: Per Default | AI15: Per Default | AK15: - | AL15: N/a | AM15: -
A16: 3.5 Need-Based Financial Aid | B16: - An aid pool is only available when the school is operating at +$10k profit/student - Anything else is an exception that needs to be approved by Joe/Mackenzie + Andy | C16: Per Default | D16: Per Default | E16: Per Default | F16: Per Default | H16: Per Default | I16: Per Default | J16: Per Default | K16: Per Default | L16: Per Default | M16: Per Default | N16: Per Default | O16: Per Default | P16: Per Default | Q16: Per Default | R16: Per Default | S16: Per Default | T16: Per Default | U16: Per Default | V16: Per Default | W16: Per Default | X16: Per Default | Y16: Per Default | Z16: Per Default | AA16: Per Default | AB16: Per Default | AF16: Per Default | AI16: Per Default | AK16: - | AL16: N/a | AM16: -
A17: 3.6 Referral Credit | B17: Referring Family: $1,000 tuition credit for one year per enrolled student referred. New Family: $1,000 tuition credit for one year per student upon enrollment. | C17: Per Default | D17: Per Default | E17: Per Default | F17: Per Default | H17: Per Default | I17: Per Default | J17: Per Default | K17: Per Default | L17: Per Default | M17: Per Default | N17: Per Default | O17: Per Default | P17: Per Default | Q17: Per Default | R17: Per Default | S17: Per Default | T17: Per Default | U17: Per Default | V17: Per Default | W17: Per Default | X17: Per Default | Y17: Per Default | Z17: Per Default | AA17: Per Default | AB17: Per Default | AF17: Per Default | AI17: Per Default | AK17: - | AL17: N/a | AM17: -
A18: 4. Grade Levels | B18: n/a | C18: Split PK–5 6-8 | D18: 9–12 | E18: K–10 | F18: PK–8 | G18: Grades 9-10 to start and will age up as students grow | H18: K-8 | I18: K-8 | J18: K-8 | K18: K-8 | L18: Current: '5-8 25/26 adding in 3 & 4 | M18: K-8 | N18: K-6 Remains K-6 in 26/27 | O18: K-8 | P18: K-8 | Q18: K-8 | R18: K-5 | S18: K-5 | T18: K-8 | U18: K-9 | V18: K-5 | W18: K-6 | X18: K-5 | Y18: K-5 | Z18: K-9 | AA18: K-8 | AB18: K-8 | AF18: K-8 | AI18: K-8 | AJ18: K-8 | AK18: - | AL18: 45724 | AM18: -
A19: 5. Opening Year Planned | B19: n/a | C19: Branded Alpha 2018 (added Middle School) | D19: 2019 | E19: 2024 | F19: 2022 (technically 2020) | G19: Fall 2026 | H19: 2024 | I19: 2024 | J19: 2025 | K19: 2024 | L19: 2024 | M19: Fall 2025 | N19: Fall 2025 | O19: Fall 2025 | P19: Fall 2025 | Q19: Fall 2025 | R19: Fall 2025 | S19: Fall 2025 | T19: Fall 2025 | U19: Fall 2025 | V19: Fall 2025 | W19: Fall 2025 | X19: Winter 2025 | Y19: Fall 2026 | Z19: Spring 2025 | AA19: Fall 2026 | AB19: Fall 2026 | AC19: Winter 2025/2026 | AD19: Winter 2025/2026 | AE19: Winter 2025/2026 | AF19: Fall 2026 | AG19: Winter 2025/2026 | AH19: NA | AI19: Fall 2026 | AJ19: Fall 2026 | AK19: - | AL19: N/a | AM19: Winter 2026
A20: 5.1 Calendar | B20: Default: Calendar A (Aug 13 - Jun 5) Other Option: Calendar B (Sep 3 - Jun 19) Calendar A: https://drive.google.com/file/d/1TTF65zOSSZB0KvIDp7w-6MnU9TQjCdky/view?usp=sharing and Calendar B: https://drive.google.com/file/d/1g13e1Rum6K-XAc92n4TOGY8GJw62p09p/view?usp=drive_link | C20: Per Default | D20: Per Default | E20: Per Default | F20: Per Default | H20: Per Default | I20: Per Default | J20: Per Default | K20: Per Default | L20: Per Default | M20: Per Default | N20: Per Default | O20: Per Default | P20: Per Default | Q20: Per Default | R20: Per Default | S20: Per Default | T20: Calendar B | U20: Calendar B | V20: Per Default | W20: Per Default | X20: Per Default | Y20: Per Default | Z20: Per Default | AA20: Per Default | AC20: Per Default | AD20: Per Default | AE20: Per Default | AF20: Per Default | AG20: Per Default | AH20: Per Default | AI20: Per Default | AK20: - | AL20: Year Round | AM20: N/A
A21: 5.2 Latest Opening Date (as of 11/29) | B21: Aug 13, Sep 3, some date in between, or TBD | C21: 45882 | D21: 45882 | E21: 45882 | F21: 45882 | H21: 45882 | I21: 45882 | J21: 45882 | K21: 45882 | L21: 45882 | M21: 46027 | N21: 45882 | O21: 45882 | P21: 45882 | Q21: 45882 | R21: 45882 | S21: 45882 | T21: 45903 | U21: 45903 | V21: 45903 | W21: 45943 | X21: Ready as soon as anyone is enrolled | Y21: Jan 26, 2026 Fence and fence mounted sign completed 11/18. CO still pending | Z21: 45820 | AA21: Nov 2026 - We have told families TBD with no date expectation. Opening date will be based on securing location, announcing and enrolling families. | AC21: 45676 | AD21: 45676 | AE21: 45690 | AF21: Opening TBD | AG21: 45688 | AH21: NA | AI21: 46296 | AJ21: TBD - need regulatory approval from school committee. When we know more, we'll share | AK21: - | AL21: N/A | AM21: 45683
A22: 5.3 Confirmed Enrollments | B22: From Enrollment Dashboard | C22: =COUNTIFs('Enrollment data'!$L:$L,C$1,'Enrollment data'!$M:$M,"<>Mock Student") -> 212 | D22: =COUNTIFs('Enrollment data'!$L:$L,D$1,'Enrollment data'!$M:$M,"<>Mock Student") -> 61 | E22: =COUNTIFs('Enrollment data'!$L:$L,E$1,'Enrollment data'!$M:$M,"<>Mock Student") -> 69 | F22: =COUNTIFs('Enrollment data'!$L:$L,F$1,'Enrollment data'!$M:$M,"<>Mock Student") -> 42 | H22: =COUNTIFs('Enrollment data'!$L:$L,H$1,'Enrollment data'!$M:$M,"<>Mock Student") -> 36 | I22: =COUNTIFs('Enrollment data'!$L:$L,I$1,'Enrollment data'!$M:$M,"<>Mock Student") -> 21 | J22: =COUNTIFs('Enrollment data'!$L:$L,J$1,'Enrollment data'!$M:$M,"<>Mock Student") -> 22 | K22: santa | L22: =COUNTIFs('Enrollment data'!$L:$L,L$1,'Enrollment data'!$M:$M,"<>Mock Student") -> 15 | M22: =COUNTIFs('Enrollment data'!$L:$L,M$1,'Enrollment data'!$M:$M,"<>Mock Student") -> 1 | N22: =COUNTIFs('Enrollment data'!$L:$L,N$1,'Enrollment data'!$M:$M,"<>Mock Student") -> 18 | O22: =COUNTIFs('Enrollment data'!$L:$L,O$1,'Enrollment data'!$M:$M,"<>Mock Student") -> 33 | P22: =COUNTIFs('Enrollment data'!$L:$L,P$1,'Enrollment data'!$M:$M,"<>Mock Student") -> 11 | Q22: =COUNTIFs('Enrollment data'!$L:$L,Q$1,'Enrollment data'!$M:$M,"<>Mock Student") -> 19 | R22: =COUNTIFs('Enrollment data'!$L:$L,R$1,'Enrollment data'!$M:$M,"<>Mock Student") -> 7 | S22: =COUNTIFs('Enrollment data'!$L:$L,S$1,'Enrollment data'!$M:$M,"<>Mock Student") -> 10 | ... AJ22: =COUNTIFs('Enrollment data'!$L:$L,AJ$1,'Enrollment data'!$M:$M,"<>Mock Student") -> 0 | AK22: - | AL22: =COUNTIFs('Enrollment data'!$L:$L,AL$1,'Enrollment data'!$M:$M,"<>Mock Student",'Enrollment data'!$M:$M,"<>spartan") -> 0 | AM22: =COUNTIFs('Enrollment data'!$L:$L,AM$1,'Enrollment data'!$M:$M,"<>Mock Student") -> 0
A23: 6. Address | B23: n/a | C23: PK-G5: 1201 Spyglass Dr, Austin, TX 78746 G6-8: 201 Colorado St, Austin, TX 78701 | D23: 201 Colorado St, Austin, TX 78701 | E23: 8000 SW 56th St, Miami, FL 33155 | F23: 591 N. Central Ave, Brownsville, TX 78521 | G23: Hopeful to use current location (591 N Central) and secure a new location for our prek-5 but still scouting | H23: 4402 Hudson Bend Rd, Austin, TX 78734 | I23: 2351 Westinghouse Rd, Georgetown, TX 78626 | J23: 7540 Ed Bluestein Road, Austin, Texas 78723 | K23: Bastrop Fitness Project 303 M.L.K. Junior Dr, Bastrop, TX 78602 | L23: 13915 US-183, Austin, TX 78717 | M23: 24905 Ranch Rd 12, Dripping Springs, TX 78620 | N23: 3017 Polar Lane, Cedar Park, TX 78613 | O23: 20624 N 76th St, Scottsdale, AZ 85255 | P23: 3300 Bryant Irvin Rd, Fort Worth, TX 76109 | Q23: 3741 Buchanan St, San Francisco, CA 94123 | R23: 353 Hiatt Drive, Palm Beach Gardens, FL 33418 | S23: 7220 Independence Pkwy, Plano, TX 75025 | T23: 180 Maiden Ln, New York, NY 10038 | U23: 27 E Cota St, Santa Barbara, CA 93101 | V23: 26462 Towne Centre Dr, Foothill Ranch, CA 92610 | W23: 4550 Walney Rd, Chantilly, VA 20151 | X23: 4755 Prosperity Church Rd, Charlotte, NC 28269 | Y23: 12600 Spruce Tree Way, Raleigh, NC 27614 | Z23: Not Public Yet | AA23: 13.8km, Carr. PR-693 Vega Alta, PR 00692 | AB23: 350 East South Water Street, Chicago, IL 60601 | AC23: 4260 El Camino Real, Palo Alto, CA 94306 | AD23: 5201 Park Blvd, Piedmont, CA 94611 | AE23: 3002 Main St, Santa Monica, CA 90405 | AF23: Not Public Yet | AG23: 1169 Canton St, Roswell, GA 30075 | AH23: Vela, 150 Lake St S, Kirkland, WA 98033 | AI23: 7108 Bradley Boulevard, Bethesda, Maryland 20817 | AJ23: 300 Cambridge St, Boston, MA 02114 | AK23: - | AL23: Online | AM23: 2205 E Hebron Pkwy Carrollton, TX 75010
A24: 6.1 Address Capacity | C24: 193 | D24: 194 | E24: 111 (when all phases of construction complete) | F24: 55* (verification in progress) | H24: 105 | I24: 115 | J24: 116 | K24: 18 | L24: 80 (verification in progress) | M24: 250* (verification in progress) Current capacity is 25. Can Add capacity quickly | N24: 25 (verification in progress) | O24: 38 | P24: 19 | Q24: 68 | R24: 25 | S24: 25 | T24: 123 + 59 separate / 190 combined (GFA limit on one but NLA on other so you get more than sum when combined) | U24: 78 | V24: 25 | W24: 25 | X24: 40 (verification in progress) | Y24: 25 | Z24: 25 (verification in progress) | AC24: 47 | AD24: 106 | AE24: 44 | AK24: - | AN24: J.C. Fischer - P1
A25: 6.2 Address County | B25: n/a | C25: Travis | D25: Travis | E25: Miami-Dade | F25: Cameron | H25: Travis | I25: Williamson | J25: Travis | K25: Bastrop | L25: Williamson | M25: Hays | N25: Williamson | O25: Maricopa | P25: Tarrant | Q25: San Francisco City-County | R25: Palm Beach | S25: Collin | T25: New York | U25: Santa Barbara | V25: Orange | W25: Fairfax | X25: Mecklenburg | Y25: Wake | Z25: Hillsborough | AK25: -
A26: 7. Accreditations | B26: Yes, Cognia | C26: PK-G5: Per Default G6-8: Cognia 7-12 happened in 2019 NCAA (pending) | D26: Yes,Cognia 7-12 happened in 2019 NCAA (pending) | E26: Per Default | F26: Per Default | H26: Per Default | I26: Per Default | L26: Per Default | AK26: - | AL26: N/a | AM26: Stephanie Ross Checking | AN26: Chris Locke - Cognia
A27: 8. Legal Entity | B27: n/a | C27: Alpha School 78746, LLC | D27: Alpha School 78701, LLC | E27: Alpha School 33155, LLC | F27: Alpha School 78521, LLC | H27: Sports Academy 78734, LLC | I27: GT.school 78626, LLC | J27: 2HL School 78723, LLC | K27: Arete Academy 78602, LLC | L27: Esports Academy, LLC | M27: Waypoint Academy 78620, LLC | N27: Montessorium School 78613, LLC | O27: Alpha School 85255, LLC | P27: Alpha School 76109, LLC | Q27: Alpha School 94123, LLC | R27: Alpha School 33418, LLC | S27: Alpha School 75025, LLC | T27: Alpha Anywhere Center, LLC | U27: Alpha School 93101, LLC | V27: Alpha School 92610, LLC | W27: Alpha School 20151, LLC | X27: Alpha School 28269, LLC | Y27: Alpha School 27614, LLC | Z27: Alpha School 33624, LLC recently created | AA27: ALPHA SCHOOL 00692, LLC | AB27: Alpha School 60601, LLC | AC27: Alpha School 94306, LLC | AD27: Alpha School 94611, LLC | AE27: Alpha School 90405, LLC | AF27: TBD | AI27: TBD | AK27: - | AL27: Sold by local distributors in ESA states (e.g., 2hr Learning FL, Inc.) | AM27: Sports Academy 75010, LLC
A28: 9. EIN | B28: n/a | C28: 87-3012777 Disregarded entity under 2HR Learning, Inc. and has not had reason to request its own EIN so disclosing 2HR Learning, Inc. EIN 87-3012777 | D28: 87-3012777 Disregarded entity under 2HR Learning, Inc. and has not had reason to request its own EIN so disclosing 2HR Learning, Inc. EIN 87-3012777 | E28: 39-2343436 Entity has its own EIN (required for banking purposes). It is a disregarded entity under 2HR Learning Inc and will 2HR Learning's EIN for income tax purposes - 87-3012777 | F28: 87-3012777 Disregarded entity under 2HR Learning, Inc. and has not had reason to request its own EIN so disclosing 2HR Learning, Inc. EIN | H28: 39-2389535 Entity has its own EIN (required for banking purposes). It is a disregarded entity under 2HR Learning Inc and will 2HR Learning's EIN for income tax purposes - 87-3012777 | I28: 39-2364421 Entity has its own EIN (required for banking purposes). It is a disregarded entity under 2HR Learning Inc and will 2HR Learning's EIN for income tax purposes - 87-3012777 | J28: 87-3012777 Disregarded entity under 2HR Learning, Inc. and has not had reason to request its own EIN so disclosing 2HR Learning, Inc. EIN | K28: 41-3611349 | L28: 87-3012777 Disregarded entity under 2HR Learning, Inc. and has not had reason to request its own EIN so disclosing 2HR Learning, Inc. EIN | N28: No EIN as disregarded entity under 2HR Learning, Inc. | O28: No EIN as disregarded entity under 2HR Learning, Inc. | P28: 87-3012777 Disregarded entity under 2HR Learning, Inc. and has not had reason to request its own EIN so disclosing 2HR Learning, Inc. EIN | Q28: No EIN as disregarded entity under 2HR Learning, Inc. | R28: No EIN as disregarded entity under 2HR Learning, Inc. | S28: 87-3012777 Disregarded entity under 2HR Learning, Inc. and has not had reason to request its own EIN so disclosing 2HR Learning, Inc. EIN | T28: No EIN as disregarded entity under 2HR Learning, Inc. | U28: 87-3012777 Disregarded entity under 2HR Learning, Inc. and has not had reason to request its own EIN so disclosing 2HR Learning, Inc. EIN | V28: No EIN as disregarded entity under 2HR Learning, Inc. | W28: No EIN as disregarded entity under 2HR Learning, Inc. | X28: 87-3012777 Disregarded entity under 2HR Learning, Inc. and has not had reason to request its own EIN so disclosing 2HR Learning, Inc. EIN | Y28: 87-3012777 Disregarded entity under 2HR Learning, Inc. and has not had reason to request its own EIN so disclosing 2HR Learning, Inc. EIN | Z28: No EIN as disregarded entity under 2HR Learning, Inc. | AA28: TBD | AF28: TBD | AI28: TBD | AK28: - | AL28: 87-3012777 | AM28: 39-2435433 Entity has its own EIN (required for banking purposes). It is a disregarded entity under 2HR Learning Inc and will 2HR Learning's EIN for income tax purposes - 87-3012777
A29: 10. NOTES | J29: (prev. Texas Prep, Nu Academy, Arete Austin) | K29: (prev. Valenta) | AK29: -
A30: 11. External Scholarships | E30: Step Up: Rejected FES-UA: reject | O30: STO: Accepted | R30: Step Up: Rejected FES-UA: reject | X30: NCSEAA ESA+ - reject Requires appointment of CPA for independent review | Z30: Step Up: Rejected FES-UA: reject | AK30: -
A31: 12.1 Head of School | C31: Heather McMahan (HoS) | D31: Chris Locke (HoS) | E31: Tasha Arnold (HoS) | F31: Paige Fults (HoS) | G31: Chris Locke (HoS)? | H31: Heather McMahan (HoS) | I31: Heather McMahan (HoS) | J31: Paige Fults (HoS) | K31: Paige Fults (HoS) | L31: Heather McMahan (HoS) | M31: Heather McMahan (HoS) | N31: Dr. Laura Mazer (HoS) | O31: Tasha Arnold (HoS) | P31: Tasha Arnold (HoS) | Q31: Tasha Arnold (HoS) | R31: Tasha Arnold (HoS) | S31: Tasha Arnold (HoS) | T31: Tasha Arnold (HoS) | U31: Tasha Arnold (HoS) | V31: Tasha Arnold (HoS) | AK31: - | AM31: Jeremy Williams (DoP until Launch)
A32: 12.15 Dean of Parents / Associate DoP | C32: Heather McMahan (DoP) | D32: Hiring ADoP | E32: Allyson Dudich (ADoP) | F32: Hiring ADoP | G32: Heather McMahan (DoP) | H32: Heather McMahan (DoP) | I32: Hiring ADoP | J32: Heather McMahan (DoP) | K32: Heather McMahan (DoP) | L32: Heather McMahan (DoP) | M32: Heather McMahan (DoP) | O32: Crystal Dorsey (DoP) | P32: Andy Gibson (DoP) Hiring (ADoP) | Q32: David Allen-Hughes | R32: Kirsten Berg (ADoP) | S32: Andy Gibson (ADoP) | T32: Hiring ADOP | U32: Scott Cody (ADoP) | V32: Scott Cody (ADoP) | W32: Shannon Guse (ADoP) | X32: Cifford Smith (ADoP) | Y32: Stephanie Dean (ADoP) | Z32: Jeremy Williams (DoP until Launch) | AA32: Jeremy Williams (DoP until Launch) | AC32: Hiring | AD32: Hiring | AE32: Kellie Mowll. Start date 3.2.2026 | AF32: Jeremy Williams (DoP until Launch) | AG32: Hiring | AH32: Hiring | AI32: Jeremy Williams (DoP until Launch) | AK32: - | AL32: Joe Marone
A33: 12.2 Head Guide (Lead Guide if no HG) | B33: Org chart | C33: PK-8: Braden Pomerantz (HG) | D33: Chris Locke (LG HS) Chloe Belvin (LG Alpha X) | E33: Josh Lezmi (HG) | F33: Morgan Swain (LG) | G33: Paige Fults? or Morgan Swain? | H33: Kelvin Childress (LG) | I33: Crystal Cybulski (LG) | J33: Malu Delgado (LG) | K33: Ashley Storms (LG) | L33: Beau Sydes (LG) | M33: Bryan Gordon (LG) | N33: Dr. Matt Bateman, Director of Academics Anna Smiley (LG) | O33: Matt Shenker (LG) | P33: Samantha DePalo (LG) | Q33: Carson Lehmann (LG) | R33: Allie Bradian (LG) | S33: Vanessa Watson (LG) | T33: Ben Gordon-Sniffen (LG) | U33: Drew Casebier (LG) | V33: Alexis Wilson (LG) | W33: Linnie Kazer (LG) | X33: Timothy Berry (LG) | Y33: Courtney Fenner (LG) | Z33: David Beaton (LG) | AA33: TBD | AF33: TBD | AI33: TBD | AK33: - | AL33: Phil Perkins (LG) | AM33: -
A34: 12.3 Facilities - Campus Coordinator or CC / Admissions Hybrid | C34: Shannon Peifer (CC) shannon.peifer@alpha.school (813) 389-0593 (also lead for $25k+ schools) | D34: Ian Huggins ian.huggins@alpha.school start date 12.8.25 (512) 240-2694 | E34: Need to hire CC Must be fluent in Spanish Phone TBD | F34: Kathrine Ledesma kathrine.ledesma@alpha.school (956) 230-6648 (Hybrid-Admissions, also lead for <$25k schools) | H34: Cyndie Jensen cyndie.jensen@sportsacademy.school (512) 387-1295 | I34: Keith Wong keith.wong@2hourlearning.com (972) 375-1622 | J34: Hiring CC (512) 686-8580 | K34: Not Yet (512) 360-8502 | L34: Christopher Ahrens christopher.ahrens@esports.school (571) 645-9825 | M34: Natasha Lince natasha.lince@alpha.school (956) 292-5092 | N34: Hiring CC/Admissions Montessori Background Highly Desired (512) 686-7923 | O34: Tetiana Vozniuk tetiana.pierson@alpha.school (503) 943-9317 | P34: Michaela Bosco (11/17 start date) michaela.bosco@alpha.school (817) 330-9327 | Q34: Maria Mejia maria.mejia@alpha.school (415) 286-5034 | R34: Hiring CC/Admissions No Special Requirements (561) 203-5791 | S34: May Dobbs (11/17 start date) may.dobbs@alpha.school (972) 246-8783 | T34: Julianne Braime (start date 11/24) (646) 363-6678 | U34: Kele Mkpado kelechi.mkpado@alpha.school (805) 500-6972 | V34: Jackie Chan jackie.chan@alpha.school (949) 229-1238 | W34: Hiring CC/Admissions Special Requirements: Needs to be employed by GP and complete addtl background check & TB test. (703) 348-7385 | X34: Jenna York jenna.york@alpha.school (704) 247-7355 | Y34: Baile Grant bailiemustard@gmail.com 2/2/26 Start Date (919) 213-0133 | Z34: Not Yet (813) 388-8473 | AA34: Not Yet | AF34: Not Yet | AI34: Not Yet | AK34: -
A35: 12.4 Campus Readiness - Ops Lead | B35: EDU Roles RACI & Escalation Matrix | C35: Aaron Crute aaron.crute@trilogy.com (404) 449-5043 | D35: Aaron Crute aaron.crute@trilogy.com (404) 449-5043 | E35: Tara Stephenson tara.stephenson@trilogy.com (704) 974-1413 | F35: Randall Grant randall.grant@trilogy.com (850) 212-6957 | H35: Sam Anderson sam.anderson@trilogy.com (317) 753 - 9863 Paternity Leave Coverage: Kevin Kongslie | I35: Tara Stephenson tara.stephenson@trilogy.com (704) 974-1413 | J35: Sam Anderson sam.anderson@trilogy.com (317) 753 - 9863 Paternity Leave Coverage: Randall Grant | K35: Randall Grant randall.grant@trilogy.com (850) 212-6957 | L35: Randall Grant randall.grant@trilogy.com (850) 212-6957 | M35: Randall Grant randall.grant@trilogy.com (850) 212-6957 | N35: Randall Grant randall.grant@trilogy.com (850) 212-6957 | O35: Jake Petersen jake.petersen@trilogy.com (712) 309-1377 | P35: Randall Grant randall.grant@trilogy.com (850) 212-6957 | Q35: Jake Petersen jake.petersen@trilogy.com (712) 309-1377 | R35: Tara Stephenson tara.stephenson@trilogy.com (704) 974-1413 | S35: Randall Grant randall.grant@trilogy.com (850) 212-6957 | T35: Kevin Kongslie kevin.kongslie@trilogy.com (609) 933-6838 | U35: Jake Petersen jake.petersen@trilogy.com (712) 309-1377 | V35: Jake Petersen jake.petersen@trilogy.com (712) 309-1377 | W35: Jake Petersen jake.petersen@trilogy.com (712) 309-1377 | X35: Jake Petersen jake.petersen@trilogy.com (712) 309-1377 | Y35: Jake Petersen jake.petersen@trilogy.com (712) 309-1377 | Z35: JR Houston jr.houston@trilogy.com (321) 890 - 5650 | AA35: JR Houston jr.houston@trilogy.com (321) 890 - 5650 | AF35: JR Houston jr.houston@trilogy.com (321) 890 - 5650 | AI35: JR Houston jr.houston@trilogy.com (321) 890 - 5650 | AK35: - | AM35: Kevin Kongslie kevin.kongslie@trilogy.com (609) 933-6838
A36: 12.5 Admissions Lead | C36: Cara Wilkinson (AD) | D36: Cara Wilkinson (AD) | E36: Bianca De La Riva (AD) bianca.delariva@alpha.school | F36: Kathrine Ledesma (CC) kathrine.ledesma@alpha.school | G36: Kathrine Ledesma (CC) kathrine.ledesma@alpha.school | H36: Amelia Dansby (AD) | I36: Amelia Dansby (AD) | J36: Kathrine Ledesma (CC) kathrine.ledesma@alpha.school | K36: Kathrine Ledesma (CC) kathrine.ledesma@alpha.school | L36: Amelia Dansby (AD) | M36: Kim Rodriguez (ADoP) | N36: Laura Mazer (HoS) | O36: Alyssa Duncan (AD) | P36: Andy Gibson (ADoP) | Q36: Nancy Wisniewski Torvund (AD) | R36: Kirsten Berg (ADoP) | S36: Andy Gibson (ADoP) | T36: Nancy Torvund - Admission Director Zara Raheem - Admissions Associate zara.raheem@alpha.school (646 ) 732-8244 | U36: Nancy Wisniewski Torvund (AD) | V36: Scott Cody (ADoP) | X36: Clifford Smith (ADoP) | Y36: Stephanie Dean (ADoP) | Z36: Morgan Petek (ADoP) | AK36: -
A37: 13.1 Security Tier | B37: Security Tiering Work Unit | C37: Tier 2 | D37: Tier 2 | E37: Tier 2 | F37: Tier 2 | H37: Tier 2 | I37: Tier 2 | J37: Tier 2 | K37: Tier 2 | L37: Tier 2 | M37: Tier 1 | N37: Tier 1 | O37: Tier 2 | P37: Tier 2 | Q37: Tier 3 | R37: Tier 2 | S37: Tier 2 | T37: Tier 2 | U37: Tier 2 | V37: Tier 2 | W37: Tier 1 | X37: Tier 2 | Y37: Tier 2 | Z37: Tier 2 | AA37: Tier 3 | AC37: Tier 2 | AD37: Tier 3 | AE37: Tier 2 | AF37: NA | AG37: Tier 2 | AH37: Tier 2 | AI37: NA | AJ37: Tier 2 | AK37: - | AL37: NA | AM37: Tier 2
A38: 13.2 Guard Status | C38: Armed: 1 Unarmed: 0 | D38: Armed: 1 Unarmed: 0 | E38: Armed: 2 Unarmed: 1 | F38: Armed: 1 Unarmed: 0 | H38: Armed: 2 Unarmed: 0 3rd Guard pending | I38: NA | J38: Armed: 1 Unarmed: 0 | K38: NA | L38: NA | M38: NA | N38: NA | O38: Armed: 0 Unarmed: 1 | P38: Armed: 0 Unarmed: 1 | Q38: Armed: 1 Unarmed: 0 | R38: NA | S38: NA | T38: Armed: 3 Unarmed: 0 Norely Castaño & Sugey Castillo & Rodney Velez (Armed) | U38: Armed: 0 Unarmed: 2 | V38: NA | W38: Armed: 0 Unarmed: 1 | X38: NA | Y38: NA | Z38: NA | AA38: NA | AC38: NA | AD38: NA | AE38: NA | AF38: NA | AG38: NA | AH38: NA | AI38: NA | AJ38: NA | AK38: - | AL38: NA | AM38: Armed: 1 Unarmed: 0
A39: 13.3 Guard Contact Info | C39: Primary: Dan Emerson - (716) 220-4927 Secondary (Backup): Josh Folmer - (512) 809-5494 | D39: Primary: Jamison Adler - (608) 440-4619 Secondary (Backup): Lloyd Carroll - (559) 273-1100 | E39: Frank Mason (Armed) - (347) 714 0691 Angel Bello (UA) - (786) 239-0256 Malcolm Styles (Armed) - (305) 582-3828 | F39: Manuel Mancha - 956-266-8635 | H39: Rodrick Piper - (512) 968 2875 Samuel Santana - (737) 291 2810 | I39: NA | J39: Jesus Menchaca - (737) 389-4071 | K39: NA | L39: NA | M39: NA | N39: NA | O39: Robert Peterson (UA) - (904) 762-6915 | P39: Donald Thomas (UA) - (817) 899 2058 | Q39: Akwame Muhammad | R39: NA | S39: NA | T39: Norely Castaño (Armed) - (347) 675-5288‬ Sugey Castillo - (718) 838-4043 Rodney Velez (929) 391-0537 | U39: Avraam Berezin (UA): (818) 421-3947 Chris Kahler (UA): (805) 819-8462 | V39: NA | W39: Rashad Talwed: 571-275-9486 | X39: NA | Y39: NA | Z39: NA | AA39: NA | AC39: NA | AD39: NA | AE39: NA | AF39: NA | AG39: NA | AH39: NA | AI39: NA | AJ39: NA | AK39: - | AL39: NA | AM39: Jon Evans (214) 440-9118
A40: 14. Facilities Quality Bar | E40: Debby Lichtner | H40: Cyndie Jensen | Q40: Steve Weir | AK40: -
...

Sheet Sheet11
D1: Square Footage of Property | E1: Number of Buildings | F1: Square Footage of Buildings | G1: Additional Attributes (Fields, Playscapes)
A3: Alpha School Austin | B3: Texas | C3: Austin | D3: 69,822 sq ft (1.6029 acres per deed) | E3: 1 | F3: 20,047 sq ft | G3: 1 playscape
A4: Alpha High School | B4: Texas | C4: Austin | D4: 69,696 sq ft (1.6 acre per LoopNet) | E4: 1 | F4: 22,000 sq ft (per lease) | G4: 0
A5: Alpha School Miami | B5: Florida | C5: Miami | D5: 65,340 sq ft (1.5 acres per lease) | E5: 3 (1 school, 2 storage buildings) | F5: 30,000 sq ft | G5: 1 playscape 1 field
A6: Alpha School Brownsville | B6: Texas | C6: Brownsville | D6: 0.343 Acres (per tax records) | E6: 1 | F6: 4417 sq ft (Tax Records) | G6: 0
A7: Texas Sports Academy | B7: Texas | C7: Austin | D7: 124,582 sq ft (2.86 acres per site plans) | E7: 2 | F7: 18,000 sq ft | G7: 2 fields 1 court
A8: GT School | B8: Texas | C8: Georgetown | D8: 3.3 acres per LoopNet | E8: 1 | F8: 12,664 sq ft | G8: 1 field: 1,415 sq ft 3 playscapes: Playscape 1: 545 sq ft Playscape 2: 2,673 sq ft Playscape 3: 1,275 sq ft (per landscape design)
A9: Nova Academy Austin | B9: Texas | C9: Austin | D9: 2.71 acres per LoopNet | E9: 4 (1 school building, 3 temp portable buildings - per lease) | F9: 8,261 sq ft | G9: 1 playcape 1 field
A10: Nova Academy Bastrop | B10: Texas | C10: Bastrop | D10: 10,457 sq ft (per lease) | E10: 1 | F10: 680 sq ft | G10: 1 field
A11: NextGen Academy | B11: Texas | C11: Austin | D11: 1.1 acres per LoopNet | E11: 1 | F11: 5,569 sq ft | G11: 0
A12: Waypoint Academy | B12: Texas | C12: Dripping Springs | D12: 588,060 sq ft (13.5 acres per lease) | E12: 3 (2 yurts, 1 storage shed) | F12: 748 sq ft (2 x 314 sq ft +1 x 120 sq ft) | G12: 0
A13: Alpha School Scottsdale | B13: Arizona | C13: Scottsdale | D13: 174,240 sq ft (4 Acre per Loop Net) | E13: 4 | F13: 20600 sq ft (per LoopNet) | G13: 1 playscape 1 basketball court 1 field
A14: Alpha School Fort Worth | B14: Texas | C14: Fort Worth | D14: 470,801 sq ft (10.808 acres per site plan) | E14: 1 | F14: 1,320 sq ft | G14: 1 field
A15: Alpha School San Francisco | B15: California | C15: San Francisco | D15: 9,699 sq ft (per LoopNet) | E15: 1 | F15: 8,099 sq ft | G15: 0
A16: Alpha School Palm Beach | B16: Florida | C16: Palm Beach | D16: 64,904 sq ft (1.49 acre per LoopNet) | E16: 2 | F16: 13,000 sq ft (whole building per LoopNet) | G16: 0
A17: Alpha School Plano | B17: Texas | C17: Plano | D17: 89,734 sq ft (2.06 Acre per LoopNet) | E17: 1 | F17: 2,002 sq ft | G17: 1 playscape 1 field
A18: Alpha Anywhere Center | B18: New York | C18: New York | D18: 1,200,000 sq ft (Per LoopNet) | E18: 1 | F18: 15,350 sq ft | G18: 0
A19: Alpha School Santa Barbara | B19: California | C19: Santa Barbara | D19: 0.81 AC per LoopNet | E19: 1 | F19: 13,820 sq ft | G19: 0
A20: Alpha School Lake Forest | B20: California | C20: Lake Forest | D20: 1.26 AC per LoopNet | E20: 1 | F20: 6,124 sq ft | G20: 1
A21: Alpha School Chantilly | B21: Virginia | C21: Chantilly | D21: 154,638 sq ft (3.55 Acres per LoopNet) | E21: 1 | F21: 24,820 sq ft | G21: 1 playscape 2 fields
A22: Alpha School Charlotte | B22: North Carolina | C22: Charlotte | D22: 4.67 Acres per LoopNet | E22: 1 | F22: 17,018 sq ft (whole building) | G22: 2 playscapes 1 field
A23: Alpha School Raleigh | B23: North Carolina | C23: Raleigh | D23: 1.45 Acres per LoopNet | E23: 1 | F23: 1,480 sq ft | G23: 2 Playscapes
A24: Alpha School Houston | B24: Texas | C24: Houston | D24: Location not cleared | E24: Location not cleared | F24: Zone: 52,000 sq ft D1: 1,500 sq ft | G24: Location not cleared
A25: Alpha School Tampa | B25: Florida | C25: Tampa | D25: NA - Location Needed | E25: NA - Location Needed | F25: NA - Location Needed | G25: NA - Location Needed
A26: Alpha School Orlando | B26: Florida | C26: Orlando | D26: NA - Location Needed | E26: NA - Location Needed | F26: NA - Location Needed | G26: NA - Location Needed
A27: Montessorium Cedar Park | B27: Texas | C27: Brushy Creek / Cedar Park | D27: 1.23 Acres per LoopNet | E27: 1 | F27: 14,462 sq ft (whole building per LoopNet) | G27: 1 playscape

Sheet Sheet7
A1: Alpha School Austin | B1: Austin | C1: PK-G5: 1201 Spyglass Dr, Austin, TX 78746 G6-8: 200 Colorado St, Austin, TX 78701
A2: Alpha High School | B2: Austin | C2: 201 Colorado St, Austin, TX 78701
A3: Alpha School Miami | B3: Florida | C3: 8000 SW 56th St, Miami, FL 33155
A4: Alpha School Brownsville | B4: Brownsville | C4: 591 N. Central Ave, Brownsville, TX
A5: Texas Sports Academy | B5: Austin | C5: 4402 Hudson Bend Rd, Austin, TX 78734
A6: GT School | B6: Georgetown | C6: 2351 Westinghouse Rd, Georgetown, TX 78626
A7: Nova Academy Austin | B7: Austin | C7: 7540 Ed Bluestein Road, Austin, Texas 78723
A8: Nova Academy Bastrop | B8: Bastrop | C8: Bastrop Fitness Project 303 M.L.K. Junior Dr, Bastrop, TX 78602
A9: NextGen Academy | B9: Austin | C9: 13915 US-183, Austin, TX 78717
A10: Waypoint Academy | B10: Dripipng Springs | C10: 24905 Ranch Rd 12, Dripping Springs, TX 78620
A11: Alpha School Scottsdale | B11: Scottsdale | C11: 20624 N 76th St, Scottsdale, AZ 85255
A12: Alpha School Fort Worth | B12: Fort Worth | C12: 3300 Bryant Irvin Rd, Fort Worth, TX 76109
... A25: Montessorium Cedar Park | B25: Brushy Creek / Cedar Park | C25: 3017 Polar Lane, Cedar Park, TX 78613

Sheet Enrollment data
A1: Full Student ID | B1: Campus ID | C1: Student ID | D1: First Name | E1: Preferred Name | F1: Last Name | G1: Date of Birth | H1: Gender | I1: Current Level | J1: Current Grade Level | K1: Student Alpha Email | L1: Campus | M1: Student Group | N1: Withdraw Date | O1: Student Portfolio URL | P1: Full Name | Q1: Level | R1: Level Value | S1: Advisor | T1: Advisor Email | U1: Grade | V1: Language | W1: Map Accomodations | X1: Admission Status
A2: =IFERROR(__xludf.DUMMYFUNCTION("FILTER( IMPORTRANGE(""1wBLO22hSTrKfDDXCrHIEZ1WCYIgyc-J2krKizrpx500"", ""Master!A:X""), ( (INDEX(IMPORTRANGE(""1wBLO22hSTrKfDDXCrHIEZ1WCYIgyc-J2krKizrpx500"", ""Master!X:X""), 0, 1)=""Enrolled"") + (INDEX(IMPORTRANGE(""1wBLO22hSTrKfDDXCrHIEZ1WC"&"YIgyc-J2krKizrpx500"", ""Master!X:X""), 0, 1)=""Pending Review"") + (INDEX(IMPORTRANGE(""1wBLO22hSTrKfDDXCrHIEZ1WCYIgyc-J2krKizrpx500"", ""Master!X:X""), 0, 1)=""Pending Re-enrollment"") ) * (INDEX(IMPORTRANGE(""1wBLO22hSTrKfDDXCrHIEZ1WCYIgyc-J2kr"&"Kizrpx500"", ""Master!M:M""), 0, 1) <> ""mock student"") ) "),"000-0189") -> 000-0189 | B2: =IFERROR(__xludf.DUMMYFUNCTION("""COMPUTED_VALUE"""),"0") -> 0 | C2: =IFERROR(__xludf.DUMMYFUNCTION("""COMPUTED_VALUE"""),"0189") -> 0189 | D2: =IFERROR(__xludf.DUMMYFUNCTION("""COMPUTED_VALUE"""),"Atlas") -> Atlas | E2: =IFERROR(__xludf.DUMMYFUNCTION("""COMPUTED_VALUE"""),"Atlas") -> Atlas | F2: =IFERROR(__xludf.DUMMYFUNCTION("""COMPUTED_VALUE"""),"Kloiber") -> Kloiber | G2: =IFERROR(__xludf.DUMMYFUNCTION("""COMPUTED_VALUE"""),"02/29/2016") -> 02/29/2016 | H2: =IFERROR(__xludf.DUMMYFUNCTION("""COMPUTED_VALUE"""),"male") -> male | I2: =IFERROR(__xludf.DUMMYFUNCTION("""COMPUTED_VALUE"""),"Level 2") -> Level 2 | J2: =IFERROR(__xludf.DUMMYFUNCTION("""COMPUTED_VALUE"""),"5") -> 5 | K2: =IFERROR(__xludf.DUMMYFUNCTION("""COMPUTED_VALUE"""),"atlas.kloiber@alpha.school") -> atlas.kloiber@alpha.school | L2: =IFERROR(__xludf.DUMMYFUNCTION("""COMPUTED_VALUE"""),"Alpha Anywhere (homeschool)") -> Alpha Anywhere (homeschool) | M2: =IFERROR(__xludf.DUMMYFUNCTION("""COMPUTED_VALUE"""),"") | N2: =IFERROR(__xludf.DUMMYFUNCTION("""COMPUTED_VALUE"""),"") | O2: =IFERROR(__xludf.DUMMYFUNCTION("""COMPUTED_VALUE"""),"https://drive.google.com/drive/folders/10T2cTQHqEJZqE-st6uFKPoI?usp=share_link") -> https://drive.google.com/drive/folders/10T2cTQHqEJZqE-st6uFKPoI?usp=share_link | P2: =IFERROR(__xludf.DUMMYFUNCTION("""COMPUTED_VALUE"""),"Atlas Kloiber") -> Atlas Kloiber | Q2: =IFERROR(__xludf.DUMMYFUNCTION("""COMPUTED_VALUE"""),"L2") -> L2 | R2: =IFERROR(__xludf.DUMMYFUNCTION("""COMPUTED_VALUE"""),2.0) -> 2 | S2: =IFERROR(__xludf.DUMMYFUNCTION("""COMPUTED_VALUE"""),"Carson Lehmann") -> Carson Lehmann | T2: =IFERROR(__xludf.DUMMYFUNCTION("""COMPUTED_VALUE"""),"carson.lehmann@alpha.school") -> carson.lehmann@alpha.school | U2: =IFERROR(__xludf.DUMMYFUNCTION("""COMPUTED_VALUE"""),"5") -> 5 | V2: =IFERROR(__xludf.DUMMYFUNCTION("""COMPUTED_VALUE"""),"") | W2: =IFERROR(__xludf.DUMMYFUNCTION("""COMPUTED_VALUE"""),"[]") -> [] | X2: =IFERROR(__xludf.DUMMYFUNCTION("""COMPUTED_VALUE"""),"Enrolled") -> Enrolled
A3: =IFERROR(__xludf.DUMMYFUNCTION("""COMPUTED_VALUE"""),"000-0208") -> 000-0208 | B3: =IFERROR(__xludf.DUMMYFUNCTION("""COMPUTED_VALUE"""),"0") -> 0 | C3: =IFERROR(__xludf.DUMMYFUNCTION("""COMPUTED_VALUE"""),"0208") -> 0208 | D3: =IFERROR(__xludf.DUMMYFUNCTION("""COMPUTED_VALUE"""),"Scotty") -> Scotty | E3: =IFERROR(__xludf.DUMMYFUNCTION("""COMPUTED_VALUE"""),"Scotty") -> Scotty | F3: =IFERROR(__xludf.DUMMYFUNCTION("""COMPUTED_VALUE"""),"Noel") -> Noel | G3: =IFERROR(__xludf.DUMMYFUNCTION("""COMPUTED_VALUE"""),"03/29/2015") -> 03/29/2015 | H3: =IFERROR(__xludf.DUMMYFUNCTION("""COMPUTED_VALUE"""),"F") -> F | I3: =IFERROR(__xludf.DUMMYFUNCTION("""COMPUTED_VALUE"""),"Level 2") -> Level 2 | J3: =IFERROR(__xludf.DUMMYFUNCTION("""COMPUTED_VALUE"""),"5") -> 5 | K3: =IFERROR(__xludf.DUMMYFUNCTION("""COMPUTED_VALUE"""),"scotty.noel@alpha.school") -> scotty.noel@alpha.school | L3: =IFERROR(__xludf.DUMMYFUNCTION("""COMPUTED_VALUE"""),"Alpha Anywhere (homeschool)") -> Alpha Anywhere (homeschool) | M3: =IFERROR(__xludf.DUMMYFUNCTION("""COMPUTED_VALUE"""),"JW") -> JW | N3: =IFERROR(__xludf.DUMMYFUNCTION("""COMPUTED_VALUE"""),"") | O3: =IFERROR(__xludf.DUMMYFUNCTION("""COMPUTED_VALUE"""),"https://drive.google.com/drive/folders/10T2cTQHqEJZqE-st6uFKPoI?usp=share_link") -> https://drive.google.com/drive/folders/10T2cTQHqEJZqE-st6uFKPoI?usp=share_link | P3: =IFERROR(__xludf.DUMMYFUNCTION("""COMPUTED_VALUE"""),"Scotty Noel") -> Scotty Noel | Q3: =IFERROR(__xludf.DUMMYFUNCTION("""COMPUTED_VALUE"""),"L2") -> L2 | R3: =IFERROR(__xludf.DUMMYFUNCTION("""COMPUTED_VALUE"""),2.0) -> 2 | S3: =IFERROR(__xludf.DUMMYFUNCTION("""COMPUTED_VALUE"""),"Carson Lehmann") -> Carson Lehmann | T3: =IFERROR(__xludf.DUMMYFUNCTION("""COMPUTED_VALUE"""),"carson.lehmann@alpha.school") -> carson.lehmann@alpha.school | U3: =IFERROR(__xludf.DUMMYFUNCTION("""COMPUTED_VALUE"""),"5") -> 5 | V3: =IFERROR(__xludf.DUMMYFUNCTION("""COMPUTED_VALUE"""),"") | W3: =IFERROR(__xludf.DUMMYFUNCTION("""COMPUTED_VALUE"""),"[]") -> [] | X3: =IFERROR(__xludf.DUMMYFUNCTION("""COMPUTED_VALUE"""),"Enrolled") -> Enrolled
A4: =IFERROR(__xludf.DUMMYFUNCTION("""COMPUTED_VALUE"""),"000-0771") -> 000-0771 | B4: =IFERROR(__xludf.DUMMYFUNCTION("""COMPUTED_VALUE"""),"0") -> 0 | C4: =IFERROR(__xludf.DUMMYFUNCTION("""COMPUTED_VALUE"""),"0771") -> 0771 | D4: =IFERROR(__xludf.DUMMYFUNCTION("""COMPUTED_VALUE"""),"Gray") -> Gray | E4: =IFERROR(__xludf.DUMMYFUNCTION("""COMPUTED_VALUE"""),"") | F4: =IFERROR(__xludf.DUMMYFUNCTION("""COMPUTED_VALUE"""),"Duffy") -> Duffy | G4: =IFERROR(__xludf.DUMMYFUNCTION("""COMPUTED_VALUE"""),"11/26/2014") -> 11/26/2014 | H4: =IFERROR(__xludf.DUMMYFUNCTION("""COMPUTED_VALUE"""),"M") -> M | I4: =IFERROR(__xludf.DUMMYFUNCTION("""COMPUTED_VALUE"""),"Level 2") -> Level 2 | J4: =IFERROR(__xludf.DUMMYFUNCTION("""COMPUTED_VALUE"""),"5") -> 5 | K4: =IFERROR(__xludf.DUMMYFUNCTION("""COMPUTED_VALUE"""),"gray.duffy@2hourlearning.com") -> gray.duffy@2hourlearning.com | L4: =IFERROR(__xludf.DUMMYFUNCTION("""COMPUTED_VALUE"""),"Alpha Anywhere (homeschool)") -> Alpha Anywhere (homeschool) | M4: =IFERROR(__xludf.DUMMYFUNCTION("""COMPUTED_VALUE"""),"") | N4: =IFERROR(__xludf.DUMMYFUNCTION("""COMPUTED_VALUE"""),"") | O4: =IFERROR(__xludf.DUMMYFUNCTION("""COMPUTED_VALUE"""),"https://drive.google.com/drive/folders/10T2cTQHqEJZqE-st6uFKPoI?usp=share_link") -> https://drive.google.com/drive/folders/10T2cTQHqEJZqE-st6uFKPoI?usp=share_link | P4: =IFERROR(__xludf.DUMMYFUNCTION("""COMPUTED_VALUE"""),"Gray Duffy") -> Gray Duffy | Q4: =IFERROR(__xludf.DUMMYFUNCTION("""COMPUTED_VALUE"""),"L2") -> L2 | R4: =IFERROR(__xludf.DUMMYFUNCTION("""COMPUTED_VALUE"""),2.0) -> 2 | S4: =IFERROR(__xludf.DUMMYFUNCTION("""COMPUTED_VALUE""")," ") | T4: =IFERROR(__xludf.DUMMYFUNCTION("""COMPUTED_VALUE"""),"") | U4: =IFERROR(__xludf.DUMMYFUNCTION("""COMPUTED_VALUE"""),"5") -> 5 | V4: =IFERROR(__xludf.DUMMYFUNCTION("""COMPUTED_VALUE"""),"English") -> English | W4: =IFERROR(__xludf.DUMMYFUNCTION("""COMPUTED_VALUE"""),"[]") -> [] | X4: =IFERROR(__xludf.DUMMYFUNCTION("""COMPUTED_VALUE"""),"Enrolled") -> Enrolled
A5: =IFERROR(__xludf.DUMMYFUNCTION("""COMPUTED_VALUE"""),"000-0777") -> 000-0777 | B5: =IFERROR(__xludf.DUMMYFUNCTION("""COMPUTED_VALUE"""),"0") -> 0 | C5: =IFERROR(__xludf.DUMMYFUNCTION("""COMPUTED_VALUE"""),"0777") -> 0777 | D5: =IFERROR(__xludf.DUMMYFUNCTION("""COMPUTED_VALUE"""),"Knox Martin") -> Knox Martin | E5: =IFERROR(__xludf.DUMMYFUNCTION("""COMPUTED_VALUE"""),"") | F5: =IFERROR(__xludf.DUMMYFUNCTION("""COMPUTED_VALUE"""),"Wheeler") -> Wheeler | G5: =IFERROR(__xludf.DUMMYFUNCTION("""COMPUTED_VALUE"""),"10/25/2013") -> 10/25/2013 | H5: =IFERROR(__xludf.DUMMYFUNCTION("""COMPUTED_VALUE"""),"Self Identify") -> Self Identify | I5: =IFERROR(__xludf.DUMMYFUNCTION("""COMPUTED_VALUE"""),"Middle School") -> Middle School | J5: =IFERROR(__xludf.DUMMYFUNCTION("""COMPUTED_VALUE"""),"6") -> 6 | K5: =IFERROR(__xludf.DUMMYFUNCTION("""COMPUTED_VALUE"""),"knox.wheeler@2hourlearning.com") -> knox.wheeler@2hourlearning.com | L5: =IFERROR(__xludf.DUMMYFUNCTION("""COMPUTED_VALUE"""),"Alpha Anywhere (homeschool)") -> Alpha Anywhere (homeschool) | M5: =IFERROR(__xludf.DUMMYFUNCTION("""COMPUTED_VALUE"""),"") | N5: =IFERROR(__xludf.DUMMYFUNCTION("""COMPUTED_VALUE"""),"") | O5: =IFERROR(__xludf.DUMMYFUNCTION("""COMPUTED_VALUE"""),"https://drive.google.com/drive/folders/10T2cTQHqEJZqE-st6uFKPoI?usp=share_link") -> https://drive.google.com/drive/folders/10T2cTQHqEJZqE-st6uFKPoI?usp=share_link | P5: =IFERROR(__xludf.DUMMYFUNCTION("""COMPUTED_VALUE"""),"Knox Martin Wheeler") -> Knox Martin Wheeler | Q5: =IFERROR(__xludf.DUMMYFUNCTION("""COMPUTED_VALUE"""),"MS") -> MS | R5: =IFERROR(__xludf.DUMMYFUNCTION("""COMPUTED_VALUE"""),0.0) -> 0 | S5: =IFERROR(__xludf.DUMMYFUNCTION("""COMPUTED_VALUE""")," ") | T5: =IFERROR(__xludf.DUMMYFUNCTION("""COMPUTED_VALUE"""),"") | U5: =IFERROR(__xludf.DUMMYFUNCTION("""COMPUTED_VALUE"""),"6") -> 6 | V5: =IFERROR(__xludf.DUMMYFUNCTION("""COMPUTED_VALUE"""),"English") -> English | W5: =IFERROR(__xludf.DUMMYFUNCTION("""COMPUTED_VALUE"""),"[]") -> [] | X5: =IFERROR(__xludf.DUMMYFUNCTION("""COMPUTED_VALUE"""),"Enrolled") -> Enrolled
A6: =IFERROR(__xludf.DUMMYFUNCTION("""COMPUTED_VALUE"""),"000-0780") -> 000-0780 | B6: =IFERROR(__xludf.DUMMYFUNCTION("""COMPUTED_VALUE"""),"0") -> 0 | C6: =IFERROR(__xludf.DUMMYFUNCTION("""COMPUTED_VALUE"""),"0780") -> 0780 | D6: =IFERROR(__xludf.DUMMYFUNCTION("""COMPUTED_VALUE"""),"Roman-Parker") -> Roman-Parker | E6: =IFERROR(__xludf.DUMMYFUNCTION("""COMPUTED_VALUE"""),"") | F6: =IFERROR(__xludf.DUMMYFUNCTION("""COMPUTED_VALUE"""),"Davis") -> Davis | G6: =IFERROR(__xludf.DUMMYFUNCTION("""COMPUTED_VALUE"""),"06/16/2015") -> 06/16/2015 | H6: =IFERROR(__xludf.DUMMYFUNCTION("""COMPUTED_VALUE"""),"Self Identify") -> Self Identify | I6: =IFERROR(__xludf.DUMMYFUNCTION("""COMPUTED_VALUE"""),"Level 2") -> Level 2 | J6: =IFERROR(__xludf.DUMMYFUNCTION("""COMPUTED_VALUE"""),"5") -> 5 | K6: =IFERROR(__xludf.DUMMYFUNCTION("""COMPUTED_VALUE"""),"roman-parker.davis@2hourlearning.com") -> roman-parker.davis@2hourlearning.com | L6: =IFERROR(__xludf.DUMMYFUNCTION("""COMPUTED_VALUE"""),"Alpha Anywhere (homeschool)") -> Alpha Anywhere (homeschool) | M6: =IFERROR(__xludf.DUMMYFUNCTION("""COMPUTED_VALUE"""),"") | N6: =IFERROR(__xludf.DUMMYFUNCTION("""COMPUTED_VALUE"""),"") | O6: =IFERROR(__xludf.DUMMYFUNCTION("""COMPUTED_VALUE"""),"https://drive.google.com/drive/folders/10T2cTQHqEJZqE-st6uFKPoI?usp=share_link") -> https://drive.google.com/drive/folders/10T2cTQHqEJZqE-st6uFKPoI?usp=share_link | P6: =IFERROR(__xludf.DUMMYFUNCTION("""COMPUTED_VALUE"""),"Roman-Parker Davis") -> Roman-Parker Davis | Q6: =IFERROR(__xludf.DUMMYFUNCTION("""COMPUTED_VALUE"""),"L2") -> L2 | R6: =IFERROR(__xludf.DUMMYFUNCTION("""COMPUTED_VALUE"""),2.0) -> 2 | S6: =IFERROR(__xludf.DUMMYFUNCTION("""COMPUTED_VALUE""")," ") | T6: =IFERROR(__xludf.DUMMYFUNCTION("""COMPUTED_VALUE"""),"") | U6: =IFERROR(__xludf.DUMMYFUNCTION("""COMPUTED_VALUE"""),"5") -> 5 | V6: =IFERROR(__xludf.DUMMYFUNCTION("""COMPUTED_VALUE"""),"English") -> English | W6: =IFERROR(__xludf.DUMMYFUNCTION("""COMPUTED_VALUE"""),"[]") -> [] | X6: =IFERROR(__xludf.DUMMYFUNCTION("""COMPUTED_VALUE"""),"Enrolled") -> Enrolled
A7: =IFERROR(__xludf.DUMMYFUNCTION("""COMPUTED_VALUE"""),"000-0783") -> 000-0783 | B7: =IFERROR(__xludf.DUMMYFUNCTION("""COMPUTED_VALUE"""),"0") -> 0 | C7: =IFERROR(__xludf.DUMMYFUNCTION("""COMPUTED_VALUE"""),"0783") -> 0783 | D7: =IFERROR(__xludf.DUMMYFUNCTION("""COMPUTED_VALUE"""),"Amelia Catherine") -> Amelia Catherine | E7: =IFERROR(__xludf.DUMMYFUNCTION("""COMPUTED_VALUE"""),"") | F7: =IFERROR(__xludf.DUMMYFUNCTION("""COMPUTED_VALUE"""),"Lucas") -> Lucas | G7: =IFERROR(__xludf.DUMMYFUNCTION("""COMPUTED_VALUE"""),"09/24/2011") -> 09/24/2011 | H7: =IFERROR(__xludf.DUMMYFUNCTION("""COMPUTED_VALUE"""),"Self Identify") -> Self Identify | I7: =IFERROR(__xludf.DUMMYFUNCTION("""COMPUTED_VALUE"""),"Middle School") -> Middle School | J7: =IFERROR(__xludf.DUMMYFUNCTION("""COMPUTED_VALUE"""),"8") -> 8 | K7: =IFERROR(__xludf.DUMMYFUNCTION("""COMPUTED_VALUE"""),"amelia.lucas@2hourlearning.com") -> amelia.lucas@2hourlearning.com | L7: =IFERROR(__xludf.DUMMYFUNCTION("""COMPUTED_VALUE"""),"Alpha Anywhere (homeschool)") -> Alpha Anywhere (homeschool) | M7: =IFERROR(__xludf.DUMMYFUNCTION("""COMPUTED_VALUE"""),"") | N7: =IFERROR(__xludf.DUMMYFUNCTION("""COMPUTED_VALUE"""),"") | O7: =IFERROR(__xludf.DUMMYFUNCTION("""COMPUTED_VALUE"""),"https://drive.google.com/drive/folders/10T2cTQHqEJZqE-st6uFKPoI?usp=share_link") -> https://drive.google.com/drive/folders/10T2cTQHqEJZqE-st6uFKPoI?usp=share_link | P7: =IFERROR(__xludf.DUMMYFUNCTION("""COMPUTED_VALUE"""),"Amelia Catherine Lucas") -> Amelia Catherine Lucas | Q7: =IFERROR(__xludf.DUMMYFUNCTION("""COMPUTED_VALUE"""),"MS") -> MS | R7: =IFERROR(__xludf.DUMMYFUNCTION("""COMPUTED_VALUE"""),0.0) -> 0 | S7: =IFERROR(__xludf.DUMMYFUNCTION("""COMPUTED_VALUE""")," ") | T7: =IFERROR(__xludf.DUMMYFUNCTION("""COMPUTED_VALUE"""),"") | U7: =IFERROR(__xludf.DUMMYFUNCTION("""COMPUTED_VALUE"""),"8") -> 8 | V7: =IFERROR(__xludf.DUMMYFUNCTION("""COMPUTED_VALUE"""),"English") -> English | W7: =IFERROR(__xludf.DUMMYFUNCTION("""COMPUTED_VALUE"""),"[]") -> [] | X7: =IFERROR(__xludf.DUMMYFUNCTION("""COMPUTED_VALUE"""),"Enrolled") -> Enrolled
A8: =IFERROR(__xludf.DUMMYFUNCTION("""COMPUTED_VALUE"""),"000-0798") -> 000-0798 | B8: =IFERROR(__xludf.DUMMYFUNCTION("""COMPUTED_VALUE"""),"0") -> 0 | C8: =IFERROR(__xludf.DUMMYFUNCTION("""COMPUTED_VALUE"""),"0798") -> 0798 | D8: =IFERROR(__xludf.DUMMYFUNCTION("""COMPUTED_VALUE"""),"Diana") -> Diana | E8: =IFERROR(__xludf.DUMMYFUNCTION("""COMPUTED_VALUE"""),"") | F8: =IFERROR(__xludf.DUMMYFUNCTION("""COMPUTED_VALUE"""),"Kostov") -> Kostov | G8: =IFERROR(__xludf.DUMMYFUNCTION("""COMPUTED_VALUE"""),"06/28/2014") -> 06/28/2014 | H8: =IFERROR(__xludf.DUMMYFUNCTION("""COMPUTED_VALUE"""),"Self Identify") -> Self Identify | I8: =IFERROR(__xludf.DUMMYFUNCTION("""COMPUTED_VALUE"""),"Middle School") -> Middle School | J8: =IFERROR(__xludf.DUMMYFUNCTION("""COMPUTED_VALUE"""),"6") -> 6 | K8: =IFERROR(__xludf.DUMMYFUNCTION("""COMPUTED_VALUE"""),"diana.kostov@2hourlearning.com") -> diana.kostov@2hourlearning.com | L8: =IFERROR(__xludf.DUMMYFUNCTION("""COMPUTED_VALUE"""),"Alpha Anywhere (homeschool)") -> Alpha Anywhere (homeschool) | M8: =IFERROR(__xludf.DUMMYFUNCTION("""COMPUTED_VALUE"""),"") | N8: =IFERROR(__xludf.DUMMYFUNCTION("""COMPUTED_VALUE"""),"") | O8: =IFERROR(__xludf.DUMMYFUNCTION("""COMPUTED_VALUE"""),"https://drive.google.com/drive/folders/10T2cTQHqEJZqE-st6uFKPoI?usp=share_link") -> https://drive.google.com/drive/folders/10T2cTQHqEJZqE-st6uFKPoI?usp=share_link | P8: =IFERROR(__xludf.DUMMYFUNCTION("""COMPUTED_VALUE"""),"Diana Kostov") -> Diana Kostov | Q8: =IFERROR(__xludf.DUMMYFUNCTION("""COMPUTED_VALUE"""),"MS") -> MS | R8: =IFERROR(__xludf.DUMMYFUNCTION("""COMPUTED_VALUE"""),0.0) -> 0 | S8: =IFERROR(__xludf.DUMMYFUNCTION("""COMPUTED_VALUE""")," ") | T8: =IFERROR(__xludf.DUMMYFUNCTION("""COMPUTED_VALUE"""),"") | U8: =IFERROR(__xludf.DUMMYFUNCTION("""COMPUTED_VALUE"""),"6") -> 6 | V8: =IFERROR(__xludf.DUMMYFUNCTION("""COMPUTED_VALUE"""),"English") -> English | W8: =IFERROR(__xludf.DUMMYFUNCTION("""COMPUTED_VALUE"""),"[]") -> [] | X8: =IFERROR(__xludf.DUMMYFUNCTION("""COMPUTED_VALUE"""),"Enrolled") -> Enrolled
A9: =IFERROR(__xludf.DUMMYFUNCTION("""COMPUTED_VALUE"""),"000-0842") -> 000-0842 | B9: =IFERROR(__xludf.DUMMYFUNCTION("""COMPUTED_VALUE"""),"0") -> 0 | C9: =IFERROR(__xludf.DUMMYFUNCTION("""COMPUTED_VALUE"""),"0842") -> 0842 | D9: =IFERROR(__xludf.DUMMYFUNCTION("""COMPUTED_VALUE"""),"Airielle") -> Airielle | E9: =IFERROR(__xludf.DUMMYFUNCTION("""COMPUTED_VALUE"""),"Airi") -> Airi | F9: =IFERROR(__xludf.DUMMYFUNCTION("""COMPUTED_VALUE"""),"Elliott") -> Elliott | G9: =IFERROR(__xludf.DUMMYFUNCTION("""COMPUTED_VALUE"""),"09/13/2013") -> 09/13/2013 | H9: =IFERROR(__xludf.DUMMYFUNCTION("""COMPUTED_VALUE"""),"female") -> female | I9: =IFERROR(__xludf.DUMMYFUNCTION("""COMPUTED_VALUE"""),"Level 2") -> Level 2 | J9: =IFERROR(__xludf.DUMMYFUNCTION("""COMPUTED_VALUE"""),"5") -> 5 | K9: =IFERROR(__xludf.DUMMYFUNCTION("""COMPUTED_VALUE"""),"airielle.elliott@2hourlearning.com") -> airielle.elliott@2hourlearning.com | L9: =IFERROR(__xludf.DUMMYFUNCTION("""COMPUTED_VALUE"""),"Alpha Anywhere (homeschool)") -> Alpha Anywhere (homeschool) | M9: =IFERROR(__xludf.DUMMYFUNCTION("""COMPUTED_VALUE"""),"") | N9: =IFERROR(__xludf.DUMMYFUNCTION("""COMPUTED_VALUE"""),"") | O9: =IFERROR(__xludf.DUMMYFUNCTION("""COMPUTED_VALUE"""),"https://drive.google.com/drive/folders/10T2cTQHqEJZqE-st6uFKPoI?usp=share_link") -> https://drive.google.com/drive/folders/10T2cTQHqEJZqE-st6uFKPoI?usp=share_link | P9: =IFERROR(__xludf.DUMMYFUNCTION("""COMPUTED_VALUE"""),"Airi Elliott") -> Airi Elliott | Q9: =IFERROR(__xludf.DUMMYFUNCTION("""COMPUTED_VALUE"""),"L2") -> L2 | R9: =IFERROR(__xludf.DUMMYFUNCTION("""COMPUTED_VALUE"""),2.0) -> 2 | S9: =IFERROR(__xludf.DUMMYFUNCTION("""COMPUTED_VALUE""")," ") | T9: =IFERROR(__xludf.DUMMYFUNCTION("""COMPUTED_VALUE"""),"") | U9: =IFERROR(__xludf.DUMMYFUNCTION("""COMPUTED_VALUE"""),"5") -> 5 | V9: =IFERROR(__xludf.DUMMYFUNCTION("""COMPUTED_VALUE"""),"") | W9: =IFERROR(__xludf.DUMMYFUNCTION("""COMPUTED_VALUE"""),"[]") -> [] | X9: =IFERROR(__xludf.DUMMYFUNCTION("""COMPUTED_VALUE"""),"Enrolled") -> Enrolled
